Workbook

Sheet Summary
A3: AI Capex and S&P 500 Earnings Growth
A4: Data coverage
A5: Metric | B5: 2025→2026 | C5: 2026→2027 | D5: Status
A6: Required companies | B6: =Assumptions!G7 -> 40 | C6: =Assumptions!G7 -> 40 | D6: Target
A7: Companies with complete inputs | B7: ='Company Model'!W45 -> 40 | C7: ='Company Model'!X45 -> 40 | D7: Calculated
A8: Missing companies | B8: =B6-B7 -> 0 | C8: =C6-C7 -> 0 | D8: Calculated
A9: Primary model status | B9: =IF(B8=0,"Ready","Awaiting inputs") -> Ready | C9: =IF(C8=0,"Ready","Awaiting inputs") -> Ready | D9: Calculated
A10: S&P EPS assumptions | B10: =Assumptions!B7&" → "&Assumptions!B8 -> 274.19 → 360 | C10: =Assumptions!B8&" → "&Assumptions!B9 -> 360 → 420 | D10: Index points
A12: Consensus-based result
A13: Metric | B13: 2025→2026 | C13: 2026→2027 | D13: Unit
A14: S&P 500 aggregate earnings increase | B14: =Assumptions!B13 -> 732.53337 | C14: =Assumptions!B14 -> 512.2014 | D14: USD bn
A15: Selected basket total earnings increase | B15: ='Company Model'!H45 -> 349.90491 | C15: ='Company Model'!I45 -> 474.05318 | D15: USD bn
A16: Broad basket share of S&P increase | B16: =B15/B14 -> 0.47766412 | C16: =C15/C14 -> 0.92552105
A17: AI-attributed share: low | B17: =(('Company Model'!P45-SUMIF('Company Model'!$C$5:$C$44,"Hyperscaler and platform",'Company Model'!$P$5:$P$44))/Assumptions!B15+SUMIF('Company Model'!$C$5:$C$44,"Hyperscaler and platform",'Company Model'!$P$5:$P$44))/B14 -> 0.29281472 | C17: =(('Company Model'!S45-SUMIF('Company Model'!$C$5:$C$44,"Hyperscaler and platform",'Company Model'!$S$5:$S$44))/Assumptions!B15+SUMIF('Company Model'!$C$5:$C$44,"Hyperscaler and platform",'Company Model'!$S$5:$S$44))/C14 -> 0.65202088
A18: AI-attributed share: base | B18: =(('Company Model'!Q45-SUMIF('Company Model'!$C$5:$C$44,"Hyperscaler and platform",'Company Model'!$Q$5:$Q$44))/Assumptions!B15+SUMIF('Company Model'!$C$5:$C$44,"Hyperscaler and platform",'Company Model'!$Q$5:$Q$44))/B14 -> 0.35327397 | C18: =(('Company Model'!T45-SUMIF('Company Model'!$C$5:$C$44,"Hyperscaler and platform",'Company Model'!$T$5:$T$44))/Assumptions!B15+SUMIF('Company Model'!$C$5:$C$44,"Hyperscaler and platform",'Company Model'!$T$5:$T$44))/C14 -> 0.7628258
A19: AI-attributed share: high | B19: =(('Company Model'!R45-SUMIF('Company Model'!$C$5:$C$44,"Hyperscaler and platform",'Company Model'!$R$5:$R$44))/Assumptions!B15+SUMIF('Company Model'!$C$5:$C$44,"Hyperscaler and platform",'Company Model'!$R$5:$R$44))/B14 -> 0.40788069 | C19: =(('Company Model'!U45-SUMIF('Company Model'!$C$5:$C$44,"Hyperscaler and platform",'Company Model'!$U$5:$U$44))/Assumptions!B15+SUMIF('Company Model'!$C$5:$C$44,"Hyperscaler and platform",'Company Model'!$U$5:$U$44))/C14 -> 0.84047844
A20: Supplier AI profit contribution: base | B20: =('Company Model'!Q45-SUMIF('Company Model'!$C$5:$C$44,"Hyperscaler and platform",'Company Model'!$Q$5:$Q$44))/B14 -> 0.27284595 | C20: =('Company Model'!T45-SUMIF('Company Model'!$C$5:$C$44,"Hyperscaler and platform",'Company Model'!$T$5:$T$44))/C14 -> 0.58861708
A21: Platform AI profit contribution: base | B21: =SUMIF('Company Model'!$C$5:$C$44,"Hyperscaler and platform",'Company Model'!$Q$5:$Q$44)/B14 -> 0.050111805 | C21: =SUMIF('Company Model'!$C$5:$C$44,"Hyperscaler and platform",'Company Model'!$T$5:$T$44)/C14 -> 0.10880683
A22: Other AI profit contribution: base | B22: =B18-B20-B21 -> 0.030316217 | C22: =C18-C20-C21 -> 0.065401898
A24: Hyperscaler and platform AI-attributed earnings increase
A25: Metric | B25: 2025→2026 | C25: 2026→2027 | D25: Unit
A26: Total platform earnings increase | B26: =SUMIF('Company Model'!$C$5:$C$44,"Hyperscaler and platform",'Company Model'!$H$5:$H$44) -> 88.602807 | C26: =SUMIF('Company Model'!$C$5:$C$44,"Hyperscaler and platform",'Company Model'!$I$5:$I$44) -> 119.56234 | D26: USD bn
A27: AI-attributed earnings increase: low | B27: =SUMIF('Company Model'!$C$5:$C$44,"Hyperscaler and platform",'Company Model'!$P$5:$P$44) -> 23.270985 | C27: =SUMIF('Company Model'!$C$5:$C$44,"Hyperscaler and platform",'Company Model'!$S$5:$S$44) -> 37.152911 | D27: USD bn
A28: AI-attributed earnings increase: base | B28: =SUMIF('Company Model'!$C$5:$C$44,"Hyperscaler and platform",'Company Model'!$Q$5:$Q$44) -> 36.708569 | C28: =SUMIF('Company Model'!$C$5:$C$44,"Hyperscaler and platform",'Company Model'!$T$5:$T$44) -> 55.731008 | D28: USD bn
A29: AI-attributed earnings increase: high | B29: =SUMIF('Company Model'!$C$5:$C$44,"Hyperscaler and platform",'Company Model'!$R$5:$R$44) -> 50.732508 | C29: =SUMIF('Company Model'!$C$5:$C$44,"Hyperscaler and platform",'Company Model'!$U$5:$U$44) -> 73.858428 | D29: USD bn
A30: Share of S&P earnings growth: low | B30: =B27/$B$14 -> 0.031767815 | C30: =C27/$C$14 -> 0.072535747
A31: Share of S&P earnings growth: base | B31: =B28/$B$14 -> 0.050111805 | C31: =C28/$C$14 -> 0.10880683
A32: Share of S&P earnings growth: high | B32: =SUMIF('Company Model'!$C$5:$C$44,"Hyperscaler and platform",'Company Model'!$R$5:$R$44)/$B$14 -> 0.069256241 | C32: =SUMIF('Company Model'!$C$5:$C$44,"Hyperscaler and platform",'Company Model'!$U$5:$U$44)/$C$14 -> 0.14419802
A34: Supplier downside sensitivity: impact on total CY2027 S&P 500 EPS
A35: Scenario | B35: Supplier AI profit shock | C35: CY2027 total EPS decline
A36: Basis: decline relative to total CY2027 S&P 500 EPS of 420, not incremental EPS.
A37: Linear supplier impact | B37: 0.05 | C37: =('Company Model'!T45-SUMIF('Company Model'!$C$5:$C$44,"Hyperscaler and platform",'Company Model'!$T$5:$T$44))*(1-'Capex Cross-check'!N11/'Capex Cross-check'!M11)/Assumptions!B10/Assumptions!B9 -> 0.022426261
A38: + Inventory and price impact | B38: 0.15 | C38: =(('Company Model'!T45-SUMIF('Company Model'!$C$5:$C$44,"Hyperscaler and platform",'Company Model'!$T$5:$T$44))*(1-'Capex Cross-check'!N11/'Capex Cross-check'!M11)+('Company Model'!V45-SUMIF('Company Model'!$C$5:$C$44,"Hyperscaler and platform",'Company Model'!$V$5:$V$44))/Assumptions!B15*B38)/Assumptions!B10/Assumptions!B9 -> 0.053735319
A39: + Margin impact | B39: 0.15 | C39: =(('Company Model'!T45-SUMIF('Company Model'!$C$5:$C$44,"Hyperscaler and platform",'Company Model'!$T$5:$T$44))*(1-'Capex Cross-check'!N11/'Capex Cross-check'!M11)+('Company Model'!V45-SUMIF('Company Model'!$C$5:$C$44,"Hyperscaler and platform",'Company Model'!$V$5:$V$44))/Assumptions!B15*(B38+B39))/Assumptions!B10/Assumptions!B9 -> 0.085044378
A41: How to read the platform result | B41: Base attributes 35%–55% of each platform’s incremental profit to AI. Low-to-high captures disclosure uncertainty.
A42: Why a 10% Capex cut can hit suppliers harder | B42: A downgrade can create excess inventory. Orders, ASPs and utilization may fall together. The 20% and 30% cases illustrate this non-linearity; they are not forecasts.
A43: Current signal | B43: The model does not assume an imminent Capex cut. Current guidance still points to rising absolute investment.
A44: Scope | B44: Consensus and Capex cross-check results overlap and must not be added.
A45: Data refresh | B45: Update all CY values, provider and as-of date from one snapshot before publication.
S50: Measure | T50: 2025→2026 | U50: 2026→2027
...

Sheet Data Request
A1: Consensus Data Request | B1: Consensus Data Request | C1: Consensus Data Request | D1: Consensus Data Request | E1: Consensus Data Request | F1: Consensus Data Request | G1: Consensus Data Request | H1: Consensus Data Request
A2: Preferred input is calendarized adjusted net income. Alternative EPS and diluted-share inputs are available. | B2: Preferred input is calendarized adjusted net income. Alternative EPS and diluted-share inputs are available. | C2: Preferred input is calendarized adjusted net income. Alternative EPS and diluted-share inputs are available. | D2: Preferred input is calendarized adjusted net income. Alternative EPS and diluted-share inputs are available. | E2: Preferred input is calendarized adjusted net income. Alternative EPS and diluted-share inputs are available. | F2: Preferred input is calendarized adjusted net income. Alternative EPS and diluted-share inputs are available. | G2: Preferred input is calendarized adjusted net income. Alternative EPS and diluted-share inputs are available. | H2: Preferred input is calendarized adjusted net income. Alternative EPS and diluted-share inputs are available.
A4: Data needed from Bloomberg, LSEG or FactSet | B4: Data needed from Bloomberg, LSEG or FactSet | C4: Data needed from Bloomberg, LSEG or FactSet | D4: Data needed from Bloomberg, LSEG or FactSet | E4: Data needed from Bloomberg, LSEG or FactSet | F4: Data needed from Bloomberg, LSEG or FactSet | G4: Data needed from Bloomberg, LSEG or FactSet | H4: Data needed from Bloomberg, LSEG or FactSet
A5: Priority | B5: Field | C5: Period | D5: Basis | E5: Unit | F5: Where to paste | G5: Required? | H5: Comment
A6: 1 | B6: Company adjusted net income | C6: CY2025 | D6: Adjusted / comparable | E6: USD bn | F6: Consensus Input E | G6: Yes | H6: 40 companies
A7: 1 | B7: Company adjusted net income consensus | C7: CY2026 and CY2027 | D7: Adjusted / comparable | E7: USD bn | F7: Consensus Input F:G | G7: Yes | H7: Calendarized, not company FY
A8: 1 | B8: Provider, as-of date and basis | C8: Same extract | D8: Metadata | E8: text/date | F8: Consensus Input L:N | G8: Yes | H8: Use the same snapshot for all companies
A9: 1 | B9: S&P 500 bottom-up EPS | C9: CY2025–CY2027 | D9: Same earnings basis | E9: index points | F9: Assumptions B7:B9 | G9: Yes | H9: Same provider and as-of date preferred
A10: 2 | B10: S&P 500 divisor | C10: As-of date | D10: Index divisor | E10: USD bn per point | F10: Assumptions B9 | G10: Preferred | H10: Current workbook uses Dec-2025 value
A11: 2 | B11: Adjusted EPS and diluted shares | C11: CY2025 and CY2026 | D11: Alternative to net income | E11: EPS and bn shares | F11: Consensus Input H:K | G11: Only if net income unavailable | H11: Workbook converts EPS × diluted shares
A12: 1 | B12: CY2027 adjusted net income consensus | C12: CY2027 | D12: Adjusted / comparable | E12: USD bn | F12: Consensus Input G | G12: Yes | H12: Required for the 2026→2027 bridge
A15: Calendarization rules when the provider cannot deliver CY values | B15: Calendarization rules when the provider cannot deliver CY values | C15: Calendarization rules when the provider cannot deliver CY values | D15: Calendarization rules when the provider cannot deliver CY values | E15: Calendarization rules when the provider cannot deliver CY values | F15: Calendarization rules when the provider cannot deliver CY values | G15: Calendarization rules when the provider cannot deliver CY values | H15: Calendarization rules when the provider cannot deliver CY values
A16: Company example | B16: Fiscal year end | C16: CY2026 annual approximation | D16: Preferred method | E16: Risk | F16: Workbook treatment
A17: December year-end | B17: Dec | C17: FY2026 | D17: Use FY2026 directly | E17: Low | F17: No conversion needed
A18: Microsoft | B18: Jun | C18: 6/12 FY2026 + 6/12 FY2027 | D18: Sum calendar-quarter estimates | E18: Seasonality | F18: User should provide CY value
A19: Oracle | B19: May | C19: 5/12 FY2026 + 7/12 FY2027 | D19: Sum or calendarize quarterly estimates | E19: Capex timing | F19: User should provide CY value
A20: NVIDIA | B20: Jan | C20: 1/12 FY2026 + 11/12 FY2027 | D20: Sum or calendarize quarterly estimates | E20: Fast growth makes weighting imprecise | F20: User should provide CY value
A21: Broadcom | B21: Oct | C21: 10/12 FY2026 + 2/12 FY2027 | D21: Sum or calendarize quarterly estimates | E21: Seasonality and acquisitions | F21: User should provide CY value
A24: Preferred delivery format | B24: One Excel or CSV table with ticker, company, CY2025–CY2027 adjusted net income, provider, as-of date and earnings basis.
A25: If only fiscal-year data are available | B25: Provide FY2025, FY2026 and FY2027 estimates plus fiscal year-end month. Calendarization will be added separately.
A26: Do not mix | B26: Do not mix GAAP net income for one company with adjusted net income for another, and do not mix snapshots from different dates without labeling them.
A27: REITs | B27: For DLR and EQIX, provide the same net-income basis if possible. FFO/AFFO may be added as a separate diagnostic but cannot be added directly to S&P net income.

Sheet Consensus Input
A1: Consensus Input
A2: Paste calendar-year values in yellow cells. CY2025–CY2027 must use one earnings basis and one consensus snapshot.
A4: Ticker | B4: Company | C4: Group | D4: FY-end month | E4: CY2025 adj. net income | F4: CY2026E adj. net income | G4: CY2027E adj. net income | H4: CY2025 adj. EPS | I4: CY2026E adj. EPS | J4: CY2027E adj. EPS | K4: CY2025 diluted shares (bn) | L4: CY2026E diluted shares (bn) | M4: CY2027E diluted shares (bn) | N4: Provider | O4: As-of date | P4: Earnings basis | Q4: Notes
A5: MSFT | B5: Microsoft | C5: Hyperscaler and platform | D5: 6 | E5: =_xlfn.XLOOKUP($A5,[1]Value!$B:$B,[1]Value!$AE:$AE,"",0)/1000 -> 105.40338 | F5: =_xlfn.XLOOKUP($A5,[1]Value!$B:$B,[1]Value!$AF:$AF,"",0)/1000 -> 130.53967 | G5: =_xlfn.XLOOKUP($A5,[1]Value!$B:$B,[1]Value!$AG:$AG,"",0)/1000 -> 153.28342 | H5: =_xlfn.XLOOKUP($A5,[1]Value!$B:$B,[1]Value!$AI:$AI,"",0) -> 14.179618 | I5: =_xlfn.XLOOKUP($A5,[1]Value!$B:$B,[1]Value!$AJ:$AJ,"",0) -> 17.567813 | J5: =_xlfn.XLOOKUP($A5,[1]Value!$B:$B,[1]Value!$AK:$AK,"",0) -> 20.428 | K5: =ROUND(E5/H5*10^9,0) -> 7433442847 | L5: =ROUND(F5/I5*10^9,0) -> 7430615581 | M5: =ROUND(G5/J5*10^9,0) -> 7503594233 | N5: Various Source | O5: 46295 | P5: Adjusted / comparable
A6: AMZN | B6: Amazon | C6: Hyperscaler and platform | D6: 12 | E6: =_xlfn.XLOOKUP($A6,[1]Value!$B:$B,[1]Value!$AE:$AE,"",0)/1000 -> 72.20889 | F6: =_xlfn.XLOOKUP($A6,[1]Value!$B:$B,[1]Value!$AF:$AF,"",0)/1000 -> 86.875779 | G6: =_xlfn.XLOOKUP($A6,[1]Value!$B:$B,[1]Value!$AG:$AG,"",0)/1000 -> 129.52585 | H6: =_xlfn.XLOOKUP($A6,[1]Value!$B:$B,[1]Value!$AI:$AI,"",0) -> 6.802993 | I6: =_xlfn.XLOOKUP($A6,[1]Value!$B:$B,[1]Value!$AJ:$AJ,"",0) -> 8.065812 | J6: =_xlfn.XLOOKUP($A6,[1]Value!$B:$B,[1]Value!$AK:$AK,"",0) -> 11.843 | K6: =ROUND(E6/H6*10^9,0) -> 10614282567 | L6: =ROUND(F6/I6*10^9,0) -> 10770865847 | M6: =ROUND(G6/J6*10^9,0) -> 10936911762 | N6: Various Source | O6: 46295 | P6: Adjusted / comparable
A7: GOOGL | B7: Alphabet | C7: Hyperscaler and platform | D7: 12 | E7: =_xlfn.XLOOKUP($A7,[1]Value!$B:$B,[1]Value!$AE:$AE,"",0)/1000 -> 106.7604 | F7: =_xlfn.XLOOKUP($A7,[1]Value!$B:$B,[1]Value!$AF:$AF,"",0)/1000 -> 137.94642 | G7: =_xlfn.XLOOKUP($A7,[1]Value!$B:$B,[1]Value!$AG:$AG,"",0)/1000 -> 179.24001 | H7: =_xlfn.XLOOKUP($A7,[1]Value!$B:$B,[1]Value!$AI:$AI,"",0) -> 8.783564 | I7: =_xlfn.XLOOKUP($A7,[1]Value!$B:$B,[1]Value!$AJ:$AJ,"",0) -> 11.765675 | J7: =_xlfn.XLOOKUP($A7,[1]Value!$B:$B,[1]Value!$AK:$AK,"",0) -> 15.697 | K7: =ROUND(E7/H7*10^9,0) -> 12154565049 | L7: =ROUND(F7/I7*10^9,0) -> 11724479641 | M7: =ROUND(G7/J7*10^9,0) -> 11418743136 | N7: Various Source | O7: 46295 | P7: Adjusted / comparable
A8: META | B8: Meta Platforms | C8: Hyperscaler and platform | D8: 12 | E8: =_xlfn.XLOOKUP($A8,[1]Value!$B:$B,[1]Value!$AE:$AE,"",0)/1000 -> 73.80388 | F8: =_xlfn.XLOOKUP($A8,[1]Value!$B:$B,[1]Value!$AF:$AF,"",0)/1000 -> 88.474229 | G8: =_xlfn.XLOOKUP($A8,[1]Value!$B:$B,[1]Value!$AG:$AG,"",0)/1000 -> 92.335596 | H8: =_xlfn.XLOOKUP($A8,[1]Value!$B:$B,[1]Value!$AI:$AI,"",0) -> 29.254844 | I8: =_xlfn.XLOOKUP($A8,[1]Value!$B:$B,[1]Value!$AJ:$AJ,"",0) -> 34.70614 | J8: =_xlfn.XLOOKUP($A8,[1]Value!$B:$B,[1]Value!$AK:$AK,"",0) -> 34.352 | K8: =ROUND(E8/H8*10^9,0) -> 2522791781 | L8: =ROUND(F8/I8*10^9,0) -> 2549238521 | M8: =ROUND(G8/J8*10^9,0) -> 2687924895 | N8: Various Source | O8: 46295 | P8: Adjusted / comparable
A9: ORCL | B9: Oracle | C9: Hyperscaler and platform | D9: 5 | E9: =_xlfn.XLOOKUP($A9,[1]Value!$B:$B,[1]Value!$AE:$AE,"",0)/1000 -> 16.158036 | F9: =_xlfn.XLOOKUP($A9,[1]Value!$B:$B,[1]Value!$AF:$AF,"",0)/1000 -> 19.101303 | G9: =_xlfn.XLOOKUP($A9,[1]Value!$B:$B,[1]Value!$AG:$AG,"",0)/1000 -> 28.114857 | H9: =_xlfn.XLOOKUP($A9,[1]Value!$B:$B,[1]Value!$AI:$AI,"",0) -> 5.708431 | I9: =_xlfn.XLOOKUP($A9,[1]Value!$B:$B,[1]Value!$AJ:$AJ,"",0) -> 6.422275 | J9: =_xlfn.XLOOKUP($A9,[1]Value!$B:$B,[1]Value!$AK:$AK,"",0) -> 9.223 | K9: =ROUND(E9/H9*10^9,0) -> 2830556457 | L9: =ROUND(F9/I9*10^9,0) -> 2974226931 | M9: =ROUND(G9/J9*10^9,0) -> 3048341863 | N9: Various Source | O9: 46295 | P9: Adjusted / comparable
A10: NVDA | B10: NVIDIA | C10: Semiconductors | D10: 1 | E10: =_xlfn.XLOOKUP($A10,[1]Value!$B:$B,[1]Value!$AE:$AE,"",0)/1000 -> 97.239846 | F10: =_xlfn.XLOOKUP($A10,[1]Value!$B:$B,[1]Value!$AF:$AF,"",0)/1000 -> 197.50448 | G10: =_xlfn.XLOOKUP($A10,[1]Value!$B:$B,[1]Value!$AG:$AG,"",0)/1000 -> 335.42452 | H10: =_xlfn.XLOOKUP($A10,[1]Value!$B:$B,[1]Value!$AI:$AI,"",0) -> 3.985983 | I10: =_xlfn.XLOOKUP($A10,[1]Value!$B:$B,[1]Value!$AJ:$AJ,"",0) -> 8.134437 | J10: =_xlfn.XLOOKUP($A10,[1]Value!$B:$B,[1]Value!$AK:$AK,"",0) -> 13.757 | K10: =ROUND(E10/H10*10^9,0) -> 24395449331 | L10: =ROUND(F10/I10*10^9,0) -> 24280043439 | M10: =ROUND(G10/J10*10^9,0) -> 24382097696 | N10: Various Source | O10: 46295 | P10: Adjusted / comparable
A11: AMD | B11: Advanced Micro Devices | C11: Semiconductors | D11: 12 | E11: =_xlfn.XLOOKUP($A11,[1]Value!$B:$B,[1]Value!$AE:$AE,"",0)/1000 -> 3.417687 | F11: =_xlfn.XLOOKUP($A11,[1]Value!$B:$B,[1]Value!$AF:$AF,"",0)/1000 -> 7.9889915 | G11: =_xlfn.XLOOKUP($A11,[1]Value!$B:$B,[1]Value!$AG:$AG,"",0)/1000 -> 22.45176 | H11: =_xlfn.XLOOKUP($A11,[1]Value!$B:$B,[1]Value!$AI:$AI,"",0) -> 2.105277 | I11: =_xlfn.XLOOKUP($A11,[1]Value!$B:$B,[1]Value!$AJ:$AJ,"",0) -> 4.859403 | J11: =_xlfn.XLOOKUP($A11,[1]Value!$B:$B,[1]Value!$AK:$AK,"",0) -> 13.367 | K11: =ROUND(E11/H11*10^9,0) -> 1623390669 | L11: =ROUND(F11/I11*10^9,0) -> 1644027366 | M11: =ROUND(G11/J11*10^9,0) -> 1679640907 | N11: Various Source | O11: 46295 | P11: Adjusted / comparable
A12: AVGO | B12: Broadcom | C12: Semiconductors | D12: 10 | E12: =_xlfn.XLOOKUP($A12,[1]Value!$B:$B,[1]Value!$AE:$AE,"",0)/1000 -> 25.954481 | F12: =_xlfn.XLOOKUP($A12,[1]Value!$B:$B,[1]Value!$AF:$AF,"",0)/1000 -> 49.062537 | G12: =_xlfn.XLOOKUP($A12,[1]Value!$B:$B,[1]Value!$AG:$AG,"",0)/1000 -> 94.280343 | H12: =_xlfn.XLOOKUP($A12,[1]Value!$B:$B,[1]Value!$AI:$AI,"",0) -> 5.503839 | I12: =_xlfn.XLOOKUP($A12,[1]Value!$B:$B,[1]Value!$AJ:$AJ,"",0) -> 10.173256 | J12: =_xlfn.XLOOKUP($A12,[1]Value!$B:$B,[1]Value!$AK:$AK,"",0) -> 19.083 | K12: =ROUND(E12/H12*10^9,0) -> 4715705060 | L12: =ROUND(F12/I12*10^9,0) -> 4822697539 | M12: =ROUND(G12/J12*10^9,0) -> 4940540953 | N12: Various Source | O12: 46295 | P12: Adjusted / comparable
A13: MU | B13: Micron Technology | C13: Semiconductors | D13: 8 | E13: =_xlfn.XLOOKUP($A13,[1]Value!$B:$B,[1]Value!$AE:$AE,"",0)/1000 -> 8.69975 | F13: =_xlfn.XLOOKUP($A13,[1]Value!$B:$B,[1]Value!$AF:$AF,"",0)/1000 -> 84.131626 | G13: =_xlfn.XLOOKUP($A13,[1]Value!$B:$B,[1]Value!$AG:$AG,"",0)/1000 -> 183.90768 | H13: =_xlfn.XLOOKUP($A13,[1]Value!$B:$B,[1]Value!$AI:$AI,"",0) -> 7.790681 | I13: =_xlfn.XLOOKUP($A13,[1]Value!$B:$B,[1]Value!$AJ:$AJ,"",0) -> 74.096561 | J13: =_xlfn.XLOOKUP($A13,[1]Value!$B:$B,[1]Value!$AK:$AK,"",0) -> 161.166 | K13: =ROUND(E13/H13*10^9,0) -> 1116686718 | L13: =ROUND(F13/I13*10^9,0) -> 1135432264 | M13: =ROUND(G13/J13*10^9,0) -> 1141107163 | N13: Various Source | O13: 46295 | P13: Adjusted / comparable
A14: INTC | B14: Intel | C14: Semiconductors | D14: 12 | E14: =_xlfn.XLOOKUP($A14,[1]Value!$B:$B,[1]Value!$AE:$AE,"",0)/1000 -> -2.9662668 | F14: =_xlfn.XLOOKUP($A14,[1]Value!$B:$B,[1]Value!$AF:$AF,"",0)/1000 -> 5.7409385 | G14: =_xlfn.XLOOKUP($A14,[1]Value!$B:$B,[1]Value!$AG:$AG,"",0)/1000 -> 9.931048 | H14: =_xlfn.XLOOKUP($A14,[1]Value!$B:$B,[1]Value!$AI:$AI,"",0) -> -0.689766 | I14: =_xlfn.XLOOKUP($A14,[1]Value!$B:$B,[1]Value!$AJ:$AJ,"",0) -> 1.123304 | J14: =_xlfn.XLOOKUP($A14,[1]Value!$B:$B,[1]Value!$AK:$AK,"",0) -> 1.868 | K14: =ROUND(E14/H14*10^9,0) -> 4300395831 | L14: =ROUND(F14/I14*10^9,0) -> 5110761241 | M14: =ROUND(G14/J14*10^9,0) -> 5316406852 | N14: Various Source | O14: 46295 | P14: Adjusted / comparable
A15: AMAT | B15: Applied Materials | C15: Semiconductor equipment and EDA | D15: 10 | E15: =_xlfn.XLOOKUP($A15,[1]Value!$B:$B,[1]Value!$AE:$AE,"",0)/1000 -> 7.545633 | F15: =_xlfn.XLOOKUP($A15,[1]Value!$B:$B,[1]Value!$AF:$AF,"",0)/1000 -> 10.222297 | G15: =_xlfn.XLOOKUP($A15,[1]Value!$B:$B,[1]Value!$AG:$AG,"",0)/1000 -> 15.000132 | H15: =_xlfn.XLOOKUP($A15,[1]Value!$B:$B,[1]Value!$AI:$AI,"",0) -> 9.385888 | I15: =_xlfn.XLOOKUP($A15,[1]Value!$B:$B,[1]Value!$AJ:$AJ,"",0) -> 12.888267 | J15: =_xlfn.XLOOKUP($A15,[1]Value!$B:$B,[1]Value!$AK:$AK,"",0) -> 18.933 | K15: =ROUND(E15/H15*10^9,0) -> 803933842 | L15: =ROUND(F15/I15*10^9,0) -> 793147537 | M15: =ROUND(G15/J15*10^9,0) -> 792274441 | N15: Various Source | O15: 46295 | P15: Adjusted / comparable
A16: LRCX | B16: Lam Research | C16: Semiconductor equipment and EDA | D16: 6 | E16: =_xlfn.XLOOKUP($A16,[1]Value!$B:$B,[1]Value!$AE:$AE,"",0)/1000 -> 5.7657591 | F16: =_xlfn.XLOOKUP($A16,[1]Value!$B:$B,[1]Value!$AF:$AF,"",0)/1000 -> 8.437886 | G16: =_xlfn.XLOOKUP($A16,[1]Value!$B:$B,[1]Value!$AG:$AG,"",0)/1000 -> 12.44552 | H16: =_xlfn.XLOOKUP($A16,[1]Value!$B:$B,[1]Value!$AI:$AI,"",0) -> 4.517797 | I16: =_xlfn.XLOOKUP($A16,[1]Value!$B:$B,[1]Value!$AJ:$AJ,"",0) -> 6.733676 | J16: =_xlfn.XLOOKUP($A16,[1]Value!$B:$B,[1]Value!$AK:$AK,"",0) -> 10.026 | K16: =ROUND(E16/H16*10^9,0) -> 1276232450 | L16: =ROUND(F16/I16*10^9,0) -> 1253087616 | M16: =ROUND(G16/J16*10^9,0) -> 1241324556 | N16: Various Source | O16: 46295 | P16: Adjusted / comparable
... A44: VST | B44: Vistra | C44: Utilities and power | D44: 12 | E44: =_xlfn.XLOOKUP($A44,[1]Value!$B:$B,[1]Value!$AE:$AE,"",0)/1000 -> 1.84562 | F44: =_xlfn.XLOOKUP($A44,[1]Value!$B:$B,[1]Value!$AF:$AF,"",0)/1000 -> 2.609099 | G44: =_xlfn.XLOOKUP($A44,[1]Value!$B:$B,[1]Value!$AG:$AG,"",0)/1000 -> 3.546333 | H44: =_xlfn.XLOOKUP($A44,[1]Value!$B:$B,[1]Value!$AI:$AI,"",0) -> 4.869483 | I44: =_xlfn.XLOOKUP($A44,[1]Value!$B:$B,[1]Value!$AJ:$AJ,"",0) -> 7.24034 | J44: =_xlfn.XLOOKUP($A44,[1]Value!$B:$B,[1]Value!$AK:$AK,"",0) -> 10.517 | K44: =ROUND(E44/H44*10^9,0) -> 379017649 | L44: =ROUND(F44/I44*10^9,0) -> 360355867 | M44: =ROUND(G44/J44*10^9,0) -> 337200057 | N44: Various Source | O44: 46295 | P44: Adjusted / comparable

Sheet Company Model
A1: Company Earnings Attribution Model
A2: Company consensus bridge for CY2025–CY2027. AI attribution is a research estimate, shown as a range.
A4: Ticker | B4: Company | C4: Group | D4: FY-end | E4: CY2025 earnings used | F4: CY2026 earnings used | G4: CY2027 earnings used | H4: 2025→2026 increase | I4: 2026→2027 increase | J4: 2026 Low AI attribution | K4: 2026 Base AI attribution | L4: 2026 High AI attribution | M4: 2027 Low AI attribution | N4: 2027 Base AI attribution | O4: 2027 High AI attribution | P4: 2026 AI profit low | Q4: 2026 AI profit base | R4: 2026 AI profit high | S4: 2027 AI profit low | T4: 2027 AI profit base | U4: 2027 AI profit high | V4: CY2027 AI Earnings | W4: 2026 input status | X4: 2027 input status | Y4: Attribution rationale
A5: MSFT | B5: Microsoft | C5: Hyperscaler and platform | D5: 6 | E5: =IF(ISNUMBER('Consensus Input'!E5),'Consensus Input'!E5,IF(AND(ISNUMBER('Consensus Input'!H5),ISNUMBER('Consensus Input'!K5)),'Consensus Input'!H5*'Consensus Input'!K5,"")) -> 105.40338 | F5: =IF(ISNUMBER('Consensus Input'!F5),'Consensus Input'!F5,IF(AND(ISNUMBER('Consensus Input'!I5),ISNUMBER('Consensus Input'!L5)),'Consensus Input'!I5*'Consensus Input'!L5,"")) -> 130.53967 | G5: 153.28342 | H5: =IF(AND(ISNUMBER(E5),ISNUMBER(F5)),F5-E5,"") -> 25.136285 | I5: =IF(AND(ISNUMBER(F5),ISNUMBER(G5)),G5-F5,"") -> 22.743758 | J5: 0.25 | K5: 0.4 | L5: 0.55 | M5: 0.3 | N5: 0.45 | O5: 0.6 | P5: =IF(ISNUMBER(H5),H5*J5,"") -> 6.2840713 | Q5: =IF(ISNUMBER(H5),H5*K5,"") -> 10.054514 | R5: =IF(ISNUMBER(H5),H5*L5,"") -> 13.824957 | S5: =IF(ISNUMBER($I5),$I5*M5,"") -> 6.8231274 | T5: =IF(ISNUMBER($I5),$I5*N5,"") -> 10.234691 | U5: =IF(ISNUMBER($I5),$I5*O5,"") -> 13.646255 | V5: =G5*N5 -> 68.97754 | W5: =IF(AND(ISNUMBER(E5),ISNUMBER(F5)),"Complete","Missing") -> Complete | X5: =IF(AND(ISNUMBER(F5),ISNUMBER(G5)),"Complete","Missing") -> Complete | Y5: AI cloud and applications; diversified earnings base
A6: AMZN | B6: Amazon | C6: Hyperscaler and platform | D6: 12 | E6: =IF(ISNUMBER('Consensus Input'!E6),'Consensus Input'!E6,IF(AND(ISNUMBER('Consensus Input'!H6),ISNUMBER('Consensus Input'!K6)),'Consensus Input'!H6*'Consensus Input'!K6,"")) -> 72.20889 | F6: =IF(ISNUMBER('Consensus Input'!F6),'Consensus Input'!F6,IF(AND(ISNUMBER('Consensus Input'!I6),ISNUMBER('Consensus Input'!L6)),'Consensus Input'!I6*'Consensus Input'!L6,"")) -> 86.875779 | G6: 129.52585 | H6: =IF(AND(ISNUMBER(E6),ISNUMBER(F6)),F6-E6,"") -> 14.666889 | I6: =IF(AND(ISNUMBER(F6),ISNUMBER(G6)),G6-F6,"") -> 42.650067 | J6: 0.2 | K6: 0.35 | L6: 0.5 | M6: 0.25 | N6: 0.4 | O6: 0.55 | P6: =IF(ISNUMBER(H6),H6*J6,"") -> 2.9333778 | Q6: =IF(ISNUMBER(H6),H6*K6,"") -> 5.1334112 | R6: =IF(ISNUMBER(H6),H6*L6,"") -> 7.3334445 | S6: =IF(ISNUMBER($I6),$I6*M6,"") -> 10.662517 | T6: =IF(ISNUMBER($I6),$I6*N6,"") -> 17.060027 | U6: =IF(ISNUMBER($I6),$I6*O6,"") -> 23.457537 | V6: =G6*N6 -> 51.810338 | W6: =IF(AND(ISNUMBER(E6),ISNUMBER(F6)),"Complete","Missing") -> Complete | X6: =IF(AND(ISNUMBER(F6),ISNUMBER(G6)),"Complete","Missing") -> Complete | Y6: AWS AI and custom silicon; retail earnings remain material
A7: GOOGL | B7: Alphabet | C7: Hyperscaler and platform | D7: 12 | E7: =IF(ISNUMBER('Consensus Input'!E7),'Consensus Input'!E7,IF(AND(ISNUMBER('Consensus Input'!H7),ISNUMBER('Consensus Input'!K7)),'Consensus Input'!H7*'Consensus Input'!K7,"")) -> 106.7604 | F7: =IF(ISNUMBER('Consensus Input'!F7),'Consensus Input'!F7,IF(AND(ISNUMBER('Consensus Input'!I7),ISNUMBER('Consensus Input'!L7)),'Consensus Input'!I7*'Consensus Input'!L7,"")) -> 137.94642 | G7: 179.24001 | H7: =IF(AND(ISNUMBER(E7),ISNUMBER(F7)),F7-E7,"") -> 31.186017 | I7: =IF(AND(ISNUMBER(F7),ISNUMBER(G7)),G7-F7,"") -> 41.293594 | J7: 0.3 | K7: 0.45 | L7: 0.6 | M7: 0.35 | N7: 0.5 | O7: 0.65 | P7: =IF(ISNUMBER(H7),H7*J7,"") -> 9.3558051 | Q7: =IF(ISNUMBER(H7),H7*K7,"") -> 14.033708 | R7: =IF(ISNUMBER(H7),H7*L7,"") -> 18.71161 | S7: =IF(ISNUMBER($I7),$I7*M7,"") -> 14.452758 | T7: =IF(ISNUMBER($I7),$I7*N7,"") -> 20.646797 | U7: =IF(ISNUMBER($I7),$I7*O7,"") -> 26.840836 | V7: =G7*N7 -> 89.620006 | W7: =IF(AND(ISNUMBER(E7),ISNUMBER(F7)),"Complete","Missing") -> Complete | X7: =IF(AND(ISNUMBER(F7),ISNUMBER(G7)),"Complete","Missing") -> Complete | Y7: Cloud and advertising benefits; investment gains require separation
A8: META | B8: Meta Platforms | C8: Hyperscaler and platform | D8: 12 | E8: =IF(ISNUMBER('Consensus Input'!E8),'Consensus Input'!E8,IF(AND(ISNUMBER('Consensus Input'!H8),ISNUMBER('Consensus Input'!K8)),'Consensus Input'!H8*'Consensus Input'!K8,"")) -> 73.80388 | F8: =IF(ISNUMBER('Consensus Input'!F8),'Consensus Input'!F8,IF(AND(ISNUMBER('Consensus Input'!I8),ISNUMBER('Consensus Input'!L8)),'Consensus Input'!I8*'Consensus Input'!L8,"")) -> 88.474229 | G8: 92.335596 | H8: =IF(AND(ISNUMBER(E8),ISNUMBER(F8)),F8-E8,"") -> 14.670349 | I8: =IF(AND(ISNUMBER(F8),ISNUMBER(G8)),G8-F8,"") -> 3.861367 | J8: 0.25 | K8: 0.4 | L8: 0.6 | M8: 0.3 | N8: 0.5 | O8: 0.7 | P8: =IF(ISNUMBER(H8),H8*J8,"") -> 3.6675873 | Q8: =IF(ISNUMBER(H8),H8*K8,"") -> 5.8681396 | R8: =IF(ISNUMBER(H8),H8*L8,"") -> 8.8022094 | S8: =IF(ISNUMBER($I8),$I8*M8,"") -> 1.1584101 | T8: =IF(ISNUMBER($I8),$I8*N8,"") -> 1.9306835 | U8: =IF(ISNUMBER($I8),$I8*O8,"") -> 2.7029569 | V8: =G8*N8 -> 46.167798 | W8: =IF(AND(ISNUMBER(E8),ISNUMBER(F8)),"Complete","Missing") -> Complete | X8: =IF(AND(ISNUMBER(F8),ISNUMBER(G8)),"Complete","Missing") -> Complete | Y8: AI affects ads and engagement but is not separately disclosed
A9: ORCL | B9: Oracle | C9: Hyperscaler and platform | D9: 5 | E9: =IF(ISNUMBER('Consensus Input'!E9),'Consensus Input'!E9,IF(AND(ISNUMBER('Consensus Input'!H9),ISNUMBER('Consensus Input'!K9)),'Consensus Input'!H9*'Consensus Input'!K9,"")) -> 16.158036 | F9: =IF(ISNUMBER('Consensus Input'!F9),'Consensus Input'!F9,IF(AND(ISNUMBER('Consensus Input'!I9),ISNUMBER('Consensus Input'!L9)),'Consensus Input'!I9*'Consensus Input'!L9,"")) -> 19.101303 | G9: 28.114857 | H9: =IF(AND(ISNUMBER(E9),ISNUMBER(F9)),F9-E9,"") -> 2.943267 | I9: =IF(AND(ISNUMBER(F9),ISNUMBER(G9)),G9-F9,"") -> 9.0135537 | J9: 0.35 | K9: 0.55 | L9: 0.7 | M9: 0.45 | N9: 0.65 | O9: 0.8 | P9: =IF(ISNUMBER(H9),H9*J9,"") -> 1.0301435 | Q9: =IF(ISNUMBER(H9),H9*K9,"") -> 1.6187969 | R9: =IF(ISNUMBER(H9),H9*L9,"") -> 2.0602869 | S9: =IF(ISNUMBER($I9),$I9*M9,"") -> 4.0560992 | T9: =IF(ISNUMBER($I9),$I9*N9,"") -> 5.8588099 | U9: =IF(ISNUMBER($I9),$I9*O9,"") -> 7.210843 | V9: =G9*N9 -> 18.274657 | W9: =IF(AND(ISNUMBER(E9),ISNUMBER(F9)),"Complete","Missing") -> Complete | X9: =IF(AND(ISNUMBER(F9),ISNUMBER(G9)),"Complete","Missing") -> Complete | Y9: OCI AI infrastructure and contracts
A10: NVDA | B10: NVIDIA | C10: Semiconductors | D10: 1 | E10: =IF(ISNUMBER('Consensus Input'!E10),'Consensus Input'!E10,IF(AND(ISNUMBER('Consensus Input'!H10),ISNUMBER('Consensus Input'!K10)),'Consensus Input'!H10*'Consensus Input'!K10,"")) -> 97.239846 | F10: =IF(ISNUMBER('Consensus Input'!F10),'Consensus Input'!F10,IF(AND(ISNUMBER('Consensus Input'!I10),ISNUMBER('Consensus Input'!L10)),'Consensus Input'!I10*'Consensus Input'!L10,"")) -> 197.50448 | G10: 335.42452 | H10: =IF(AND(ISNUMBER(E10),ISNUMBER(F10)),F10-E10,"") -> 100.26464 | I10: =IF(AND(ISNUMBER(F10),ISNUMBER(G10)),G10-F10,"") -> 137.92003 | J10: 0.9 | K10: 0.95 | L10: 1 | M10: 0.94 | N10: 0.98 | O10: 1 | P10: =IF(ISNUMBER(H10),H10*J10,"") -> 90.238174 | Q10: =IF(ISNUMBER(H10),H10*K10,"") -> 95.251406 | R10: =IF(ISNUMBER(H10),H10*L10,"") -> 100.26464 | S10: =IF(ISNUMBER($I10),$I10*M10,"") -> 129.64483 | T10: =IF(ISNUMBER($I10),$I10*N10,"") -> 135.16163 | U10: =IF(ISNUMBER($I10),$I10*O10,"") -> 137.92003 | V10: =G10*N10 -> 328.71603 | W10: =IF(AND(ISNUMBER(E10),ISNUMBER(F10)),"Complete","Missing") -> Complete | X10: =IF(AND(ISNUMBER(F10),ISNUMBER(G10)),"Complete","Missing") -> Complete | Y10: AI accelerator earnings exposure
A11: AMD | B11: Advanced Micro Devices | C11: Semiconductors | D11: 12 | E11: =IF(ISNUMBER('Consensus Input'!E11),'Consensus Input'!E11,IF(AND(ISNUMBER('Consensus Input'!H11),ISNUMBER('Consensus Input'!K11)),'Consensus Input'!H11*'Consensus Input'!K11,"")) -> 3.417687 | F11: =IF(ISNUMBER('Consensus Input'!F11),'Consensus Input'!F11,IF(AND(ISNUMBER('Consensus Input'!I11),ISNUMBER('Consensus Input'!L11)),'Consensus Input'!I11*'Consensus Input'!L11,"")) -> 7.9889915 | G11: 22.45176 | H11: =IF(AND(ISNUMBER(E11),ISNUMBER(F11)),F11-E11,"") -> 4.5713045 | I11: =IF(AND(ISNUMBER(F11),ISNUMBER(G11)),G11-F11,"") -> 14.462768 | J11: 0.5 | K11: 0.7 | L11: 0.85 | M11: 0.6 | N11: 0.8 | O11: 0.9 | P11: =IF(ISNUMBER(H11),H11*J11,"") -> 2.2856522 | Q11: =IF(ISNUMBER(H11),H11*K11,"") -> 3.1999131 | R11: =IF(ISNUMBER(H11),H11*L11,"") -> 3.8856088 | S11: =IF(ISNUMBER($I11),$I11*M11,"") -> 8.6776611 | T11: =IF(ISNUMBER($I11),$I11*N11,"") -> 11.570215 | U11: =IF(ISNUMBER($I11),$I11*O11,"") -> 13.016492 | V11: =G11*N11 -> 17.961408 | W11: =IF(AND(ISNUMBER(E11),ISNUMBER(F11)),"Complete","Missing") -> Complete | X11: =IF(AND(ISNUMBER(F11),ISNUMBER(G11)),"Complete","Missing") -> Complete | Y11: Data-center GPU and CPU exposure
A12: AVGO | B12: Broadcom | C12: Semiconductors | D12: 10 | E12: =IF(ISNUMBER('Consensus Input'!E12),'Consensus Input'!E12,IF(AND(ISNUMBER('Consensus Input'!H12),ISNUMBER('Consensus Input'!K12)),'Consensus Input'!H12*'Consensus Input'!K12,"")) -> 25.954481 | F12: =IF(ISNUMBER('Consensus Input'!F12),'Consensus Input'!F12,IF(AND(ISNUMBER('Consensus Input'!I12),ISNUMBER('Consensus Input'!L12)),'Consensus Input'!I12*'Consensus Input'!L12,"")) -> 49.062537 | G12: 94.280343 | H12: =IF(AND(ISNUMBER(E12),ISNUMBER(F12)),F12-E12,"") -> 23.108055 | I12: =IF(AND(ISNUMBER(F12),ISNUMBER(G12)),G12-F12,"") -> 45.217806 | J12: 0.7 | K12: 0.85 | L12: 0.95 | M12: 0.8 | N12: 0.9 | O12: 0.97 | P12: =IF(ISNUMBER(H12),H12*J12,"") -> 16.175639 | Q12: =IF(ISNUMBER(H12),H12*K12,"") -> 19.641847 | R12: =IF(ISNUMBER(H12),H12*L12,"") -> 21.952652 | S12: =IF(ISNUMBER($I12),$I12*M12,"") -> 36.174245 | T12: =IF(ISNUMBER($I12),$I12*N12,"") -> 40.696026 | U12: =IF(ISNUMBER($I12),$I12*O12,"") -> 43.861272 | V12: =G12*N12 -> 84.852309 | W12: =IF(AND(ISNUMBER(E12),ISNUMBER(F12)),"Complete","Missing") -> Complete | X12: =IF(AND(ISNUMBER(F12),ISNUMBER(G12)),"Complete","Missing") -> Complete | Y12: Custom silicon and networking
A13: MU | B13: Micron Technology | C13: Semiconductors | D13: 8 | E13: =IF(ISNUMBER('Consensus Input'!E13),'Consensus Input'!E13,IF(AND(ISNUMBER('Consensus Input'!H13),ISNUMBER('Consensus Input'!K13)),'Consensus Input'!H13*'Consensus Input'!K13,"")) -> 8.69975 | F13: =IF(ISNUMBER('Consensus Input'!F13),'Consensus Input'!F13,IF(AND(ISNUMBER('Consensus Input'!I13),ISNUMBER('Consensus Input'!L13)),'Consensus Input'!I13*'Consensus Input'!L13,"")) -> 84.131626 | G13: 183.90768 | H13: =IF(AND(ISNUMBER(E13),ISNUMBER(F13)),F13-E13,"") -> 75.431876 | I13: =IF(AND(ISNUMBER(F13),ISNUMBER(G13)),G13-F13,"") -> 99.776051 | J13: 0.65 | K13: 0.8 | L13: 0.9 | M13: 0.75 | N13: 0.9 | O13: 0.95 | P13: =IF(ISNUMBER(H13),H13*J13,"") -> 49.030719 | Q13: =IF(ISNUMBER(H13),H13*K13,"") -> 60.345501 | R13: =IF(ISNUMBER(H13),H13*L13,"") -> 67.888688 | S13: =IF(ISNUMBER($I13),$I13*M13,"") -> 74.832038 | T13: =IF(ISNUMBER($I13),$I13*N13,"") -> 89.798446 | U13: =IF(ISNUMBER($I13),$I13*O13,"") -> 94.787248 | V13: =G13*N13 -> 165.51691 | W13: =IF(AND(ISNUMBER(E13),ISNUMBER(F13)),"Complete","Missing") -> Complete | X13: =IF(AND(ISNUMBER(F13),ISNUMBER(G13)),"Complete","Missing") -> Complete | Y13: HBM and data-center memory
A14: INTC | B14: Intel | C14: Semiconductors | D14: 12 | E14: =IF(ISNUMBER('Consensus Input'!E14),'Consensus Input'!E14,IF(AND(ISNUMBER('Consensus Input'!H14),ISNUMBER('Consensus Input'!K14)),'Consensus Input'!H14*'Consensus Input'!K14,"")) -> -2.9662668 | F14: =IF(ISNUMBER('Consensus Input'!F14),'Consensus Input'!F14,IF(AND(ISNUMBER('Consensus Input'!I14),ISNUMBER('Consensus Input'!L14)),'Consensus Input'!I14*'Consensus Input'!L14,"")) -> 5.7409385 | G14: 9.931048 | H14: =IF(AND(ISNUMBER(E14),ISNUMBER(F14)),F14-E14,"") -> 8.7072054 | I14: =IF(AND(ISNUMBER(F14),ISNUMBER(G14)),G14-F14,"") -> 4.1901095 | J14: 0.1 | K14: 0.25 | L14: 0.4 | M14: 0.3 | N14: 0.45 | O14: 0.6 | P14: =IF(ISNUMBER(H14),H14*J14,"") -> 0.87072054 | Q14: =IF(ISNUMBER(H14),H14*K14,"") -> 2.1768013 | R14: =IF(ISNUMBER(H14),H14*L14,"") -> 3.4828822 | S14: =IF(ISNUMBER($I14),$I14*M14,"") -> 1.2570328 | T14: =IF(ISNUMBER($I14),$I14*N14,"") -> 1.8855493 | U14: =IF(ISNUMBER($I14),$I14*O14,"") -> 2.5140657 | V14: =G14*N14 -> 4.4689716 | W14: =IF(AND(ISNUMBER(E14),ISNUMBER(F14)),"Complete","Missing") -> Complete | X14: =IF(AND(ISNUMBER(F14),ISNUMBER(G14)),"Complete","Missing") -> Complete | Y14: AI exposure offset by other businesses and restructuring
A15: AMAT | B15: Applied Materials | C15: Semiconductor equipment and EDA | D15: 10 | E15: =IF(ISNUMBER('Consensus Input'!E15),'Consensus Input'!E15,IF(AND(ISNUMBER('Consensus Input'!H15),ISNUMBER('Consensus Input'!K15)),'Consensus Input'!H15*'Consensus Input'!K15,"")) -> 7.545633 | F15: =IF(ISNUMBER('Consensus Input'!F15),'Consensus Input'!F15,IF(AND(ISNUMBER('Consensus Input'!I15),ISNUMBER('Consensus Input'!L15)),'Consensus Input'!I15*'Consensus Input'!L15,"")) -> 10.222297 | G15: 15.000132 | H15: =IF(AND(ISNUMBER(E15),ISNUMBER(F15)),F15-E15,"") -> 2.6766642 | I15: =IF(AND(ISNUMBER(F15),ISNUMBER(G15)),G15-F15,"") -> 4.7778348 | J15: 0.15 | K15: 0.25 | L15: 0.35 | M15: 0.2 | N15: 0.3 | O15: 0.4 | P15: =IF(ISNUMBER(H15),H15*J15,"") -> 0.40149963 | Q15: =IF(ISNUMBER(H15),H15*K15,"") -> 0.66916606 | R15: =IF(ISNUMBER(H15),H15*L15,"") -> 0.93683248 | S15: =IF(ISNUMBER($I15),$I15*M15,"") -> 0.95556695 | T15: =IF(ISNUMBER($I15),$I15*N15,"") -> 1.4333504 | U15: =IF(ISNUMBER($I15),$I15*O15,"") -> 1.9111339 | V15: =G15*N15 -> 4.5000396 | W15: =IF(AND(ISNUMBER(E15),ISNUMBER(F15)),"Complete","Missing") -> Complete | X15: =IF(AND(ISNUMBER(F15),ISNUMBER(G15)),"Complete","Missing") -> Complete | Y15: AI-linked foundry and memory equipment demand
A16: LRCX | B16: Lam Research | C16: Semiconductor equipment and EDA | D16: 6 | E16: =IF(ISNUMBER('Consensus Input'!E16),'Consensus Input'!E16,IF(AND(ISNUMBER('Consensus Input'!H16),ISNUMBER('Consensus Input'!K16)),'Consensus Input'!H16*'Consensus Input'!K16,"")) -> 5.7657591 | F16: =IF(ISNUMBER('Consensus Input'!F16),'Consensus Input'!F16,IF(AND(ISNUMBER('Consensus Input'!I16),ISNUMBER('Consensus Input'!L16)),'Consensus Input'!I16*'Consensus Input'!L16,"")) -> 8.437886 | G16: 12.44552 | H16: =IF(AND(ISNUMBER(E16),ISNUMBER(F16)),F16-E16,"") -> 2.6721269 | I16: =IF(AND(ISNUMBER(F16),ISNUMBER(G16)),G16-F16,"") -> 4.007634 | J16: 0.2 | K16: 0.3 | L16: 0.4 | M16: 0.35 | N16: 0.35 | O16: 0.45 | P16: =IF(ISNUMBER(H16),H16*J16,"") -> 0.53442537 | Q16: =IF(ISNUMBER(H16),H16*K16,"") -> 0.80163806 | R16: =IF(ISNUMBER(H16),H16*L16,"") -> 1.0688507 | S16: =IF(ISNUMBER($I16),$I16*M16,"") -> 1.4026719 | T16: =IF(ISNUMBER($I16),$I16*N16,"") -> 1.4026719 | U16: =IF(ISNUMBER($I16),$I16*O16,"") -> 1.8034353 | V16: =G16*N16 -> 4.355932 | W16: =IF(AND(ISNUMBER(E16),ISNUMBER(F16)),"Complete","Missing") -> Complete | X16: =IF(AND(ISNUMBER(F16),ISNUMBER(G16)),"Complete","Missing") -> Complete | Y16: Memory and advanced-node equipment
... A44: VST | B44: Vistra | C44: Utilities and power | D44: 12 | E44: =IF(ISNUMBER('Consensus Input'!E44),'Consensus Input'!E44,IF(AND(ISNUMBER('Consensus Input'!H44),ISNUMBER('Consensus Input'!K44)),'Consensus Input'!H44*'Consensus Input'!K44,"")) -> 1.84562 | F44: =IF(ISNUMBER('Consensus Input'!F44),'Consensus Input'!F44,IF(AND(ISNUMBER('Consensus Input'!I44),ISNUMBER('Consensus Input'!L44)),'Consensus Input'!I44*'Consensus Input'!L44,"")) -> 2.609099 | G44: 3.546333 | H44: =IF(AND(ISNUMBER(E44),ISNUMBER(F44)),F44-E44,"") -> 0.763479 | I44: =IF(AND(ISNUMBER(F44),ISNUMBER(G44)),G44-F44,"") -> 0.937234 | J44: 0.1 | K44: 0.2 | L44: 0.35 | M44: 0.15 | N44: 0.3 | O44: 0.45 | P44: =IF(ISNUMBER(H44),H44*J44,"") -> 0.0763479 | Q44: =IF(ISNUMBER(H44),H44*K44,"") -> 0.1526958 | R44: =IF(ISNUMBER(H44),H44*L44,"") -> 0.26721765 | S44: =IF(ISNUMBER($I44),$I44*M44,"") -> 0.1405851 | T44: =IF(ISNUMBER($I44),$I44*N44,"") -> 0.2811702 | U44: =IF(ISNUMBER($I44),$I44*O44,"") -> 0.4217553 | V44: =G44*N44 -> 1.0638999 | W44: =IF(AND(ISNUMBER(E44),ISNUMBER(F44)),"Complete","Missing") -> Complete | X44: =IF(AND(ISNUMBER(F44),ISNUMBER(G44)),"Complete","Missing") -> Complete | Y44: Power demand and contracting
A45: Total / coverage | E45: =SUM(E5:E44) -> 583.91053 | F45: =SUM(F5:F44) -> 933.81544 | G45: =SUM(G5:G44) -> 1407.8686 | H45: =SUM(H5:H44) -> 349.90491 | I45: =SUM(I5:I44) -> 474.05318 | P45: =SUM(P5:P44) -> 195.374 | Q45: =SUM(Q5:Q44) -> 236.57733 | R45: =SUM(R5:R44) -> 273.98085 | S45: =SUM(S5:S44) -> 304.2847 | T45: =SUM(T5:T44) -> 357.2215 | U45: =SUM(U5:U44) -> 394.83065 | V45: =SUM(V5:V44) -> 948.38517 | W45: =COUNTIF(W5:W44,"Complete") -> 40 | X45: =COUNTIF(X5:X44,"Complete") -> 40

Sheet Capex Cross-check
A1: Capex Cross-check | B1: Capex Cross-check | C1: Capex Cross-check | D1: Capex Cross-check | E1: Capex Cross-check | F1: Capex Cross-check | G1: Capex Cross-check | H1: Capex Cross-check | I1: Capex Cross-check | J1: Capex Cross-check | K1: Capex Cross-check | L1: Capex Cross-check | M1: Capex Cross-check | N1: Capex Cross-check | O1: Capex Cross-check | P1: Capex Cross-check | Q1: Capex Cross-check | R1: Capex Cross-check
A2: Secondary sensitivity only. It does not use company-specific market-share assumptions and does not drive the primary result. | B2: Secondary sensitivity only. It does not use company-specific market-share assumptions and does not drive the primary result. | C2: Secondary sensitivity only. It does not use company-specific market-share assumptions and does not drive the primary result. | D2: Secondary sensitivity only. It does not use company-specific market-share assumptions and does not drive the primary result. | E2: Secondary sensitivity only. It does not use company-specific market-share assumptions and does not drive the primary result. | F2: Secondary sensitivity only. It does not use company-specific market-share assumptions and does not drive the primary result. | G2: Secondary sensitivity only. It does not use company-specific market-share assumptions and does not drive the primary result. | H2: Secondary sensitivity only. It does not use company-specific market-share assumptions and does not drive the primary result. | I2: Secondary sensitivity only. It does not use company-specific market-share assumptions and does not drive the primary result. | J2: Secondary sensitivity only. It does not use company-specific market-share assumptions and does not drive the primary result. | K2: Secondary sensitivity only. It does not use company-specific market-share assumptions and does not drive the primary result. | L2: Secondary sensitivity only. It does not use company-specific market-share assumptions and does not drive the primary result. | M2: Secondary sensitivity only. It does not use company-specific market-share assumptions and does not drive the primary result. | N2: Secondary sensitivity only. It does not use company-specific market-share assumptions and does not drive the primary result. | O2: Secondary sensitivity only. It does not use company-specific market-share assumptions and does not drive the primary result. | P2: Secondary sensitivity only. It does not use company-specific market-share assumptions and does not drive the primary result. | Q2: Secondary sensitivity only. It does not use company-specific market-share assumptions and does not drive the primary result. | R2: Secondary sensitivity only. It does not use company-specific market-share assumptions and does not drive the primary result.
A4: Hyperscaler capex proxy | B4: Hyperscaler capex proxy | C4: Hyperscaler capex proxy | D4: Hyperscaler capex proxy | E4: Hyperscaler capex proxy | F4: Hyperscaler capex proxy | G4: Hyperscaler capex proxy | H4: Hyperscaler capex proxy | I4: Hyperscaler capex proxy | J4: Hyperscaler capex proxy
A5: Company | B5: 2025 capex | C5: 2026 capex | D5: 2025 AI share | E5: 2026 AI share | F5: 2025 AI capex | G5: 2026 AI capex | H5: Increase | I5: Period status | J5: Source | K5: 2027 capex | L5: 2027 AI share | M5: Increase | N5: Increase with 5% cut
A6: Amazon | B6: 128.3 | C6: 200 | D6: 0.75 | E6: 0.8 | F6: =B6*D6 -> 96.225 | G6: =C6*E6 -> 160 | H6: =G6-F6 -> 63.775 | I6: Calendar year | J6: Company disclosure
A7: Microsoft | B7: 64.6 | C7: 175 | D7: 0.85 | E7: 0.9 | F7: =B7*D7 -> 54.91 | G7: =C7*E7 -> 157.5 | H7: =G7-F7 -> 102.59 | I7: 2025 fiscal proxy / 2026 calendar | J7: Replace 2025 with calendarized data
A8: Alphabet | B8: 91.4 | C8: 180 | D8: 0.85 | E8: 0.9 | F8: =B8*D8 -> 77.69 | G8: =C8*E8 -> 162 | H8: =G8-F8 -> 84.31 | I8: Calendar year | J8: Company disclosure
A9: Meta | B9: 72.2 | C9: 135 | D9: 0.85 | E9: 0.9 | F9: =B9*D9 -> 61.37 | G9: =C9*E9 -> 121.5 | H9: =G9-F9 -> 60.13 | I9: Calendar year | J9: Company disclosure
A10: Oracle / residual | B10: 55.5 | C10: 64 | D10: 0.9 | E10: 0.95 | F10: =B10*D10 -> 49.95 | G10: =C10*E10 -> 60.8 | H10: =G10-F10 -> 10.85 | I10: Mixed-period proxy | J10: Replace with calendarized data
A11: Total | B11: =SUM(B6:B10) -> 412 | C11: =SUM(C6:C10) -> 754 | F11: =SUM(F6:F10) -> 340.145 | G11: =SUM(G6:G10) -> 661.8 | H11: =SUM(H6:H10) -> 321.655 | K11: 905 | L11: =K11*0.9 -> 814.5 | M11: =L11-G11 -> 152.7 | N11: =K11*(1-Summary!B37)*0.9-G11 -> 111.975
A14: Category-level sensitivity with separate 2025 and 2026 allocation assumptions | B14: Category-level sensitivity with separate 2025 and 2026 allocation assumptions | C14: Category-level sensitivity with separate 2025 and 2026 allocation assumptions | D14: Category-level sensitivity with separate 2025 and 2026 allocation assumptions | E14: Category-level sensitivity with separate 2025 and 2026 allocation assumptions | F14: Category-level sensitivity with separate 2025 and 2026 allocation assumptions | G14: Category-level sensitivity with separate 2025 and 2026 allocation assumptions | H14: Category-level sensitivity with separate 2025 and 2026 allocation assumptions | I14: Category-level sensitivity with separate 2025 and 2026 allocation assumptions | J14: Category-level sensitivity with separate 2025 and 2026 allocation assumptions | K14: Category-level sensitivity with separate 2025 and 2026 allocation assumptions | L14: Category-level sensitivity with separate 2025 and 2026 allocation assumptions | M14: Category-level sensitivity with separate 2025 and 2026 allocation assumptions | N14: Category-level sensitivity with separate 2025 and 2026 allocation assumptions | O14: Category-level sensitivity with separate 2025 and 2026 allocation assumptions | P14: Category-level sensitivity with separate 2025 and 2026 allocation assumptions | Q14: Category-level sensitivity with separate 2025 and 2026 allocation assumptions | R14: Category-level sensitivity with separate 2025 and 2026 allocation assumptions
A15: Category | B15: 2025 share | C15: 2026 share | D15: 2025 AI capex | E15: 2026 AI capex | F15: Capex increase | G15: S&P capture low | H15: S&P capture base | I15: S&P capture high | J15: Recognition | K15: Margin low | L15: Margin base | M15: Margin high | N15: Low profit | O15: Base profit | P15: High profit | Q15: Source / rationale | R15: Data status
A16: Accelerators and custom silicon | B16: 0.35 | C16: 0.36 | D16: =$F$11*B16 -> 119.05075 | E16: =$G$11*C16 -> 238.248 | F16: =E16-D16 -> 119.19725 | G16: 0.85 | H16: 0.9 | I16: 0.95 | J16: 1 | K16: 0.6 | L16: 0.7 | M16: 0.8 | N16: =F16*G16*J16*K16 -> 60.790597 | O16: =F16*H16*J16*L16 -> 75.094267 | P16: =F16*I16*J16*M16 -> 90.58991 | Q16: Server-cost benchmarks and AI accelerator exposure | R16: Research assumption
A17: Memory | B17: 0.06 | C17: 0.11 | D17: =$F$11*B17 -> 20.4087 | E17: =$G$11*C17 -> 72.798 | F17: =E17-D17 -> 52.3893 | G17: 0.65 | H17: 0.8 | I17: 0.9 | J17: 0.95 | K17: 0.65 | L17: 0.75 | M17: 0.85 | N17: =F17*G17*J17*K17 -> 21.027755 | O17: =F17*H17*J17*L17 -> 29.861901 | P17: =F17*I17*J17*M17 -> 38.073924 | Q17: Higher memory prices and content in 2026 | R17: Research assumption
A18: Networking and optics | B18: 0.12 | C18: 0.13 | D18: =$F$11*B18 -> 40.8174 | E18: =$G$11*C18 -> 86.034 | F18: =E18-D18 -> 45.2166 | G18: 0.4 | H18: 0.5 | I18: 0.6 | J18: 0.9 | K18: 0.3 | L18: 0.4 | M18: 0.5 | N18: =F18*G18*J18*K18 -> 4.8833928 | O18: =F18*H18*J18*L18 -> 8.138988 | P18: =F18*I18*J18*M18 -> 12.208482 | Q18: Networking intensity and S&P-listed suppliers | R18: Research assumption
A19: Server and storage value-add | B19: 0.08 | C19: 0.07 | D19: =$F$11*B19 -> 27.2116 | E19: =$G$11*C19 -> 46.326 | F19: =E19-D19 -> 19.1144 | G19: 0.4 | H19: 0.55 | I19: 0.7 | J19: 0.9 | K19: 0.3 | L19: 0.4 | M19: 0.5 | N19: =F19*G19*J19*K19 -> 2.0643552 | O19: =F19*H19*J19*L19 -> 3.7846512 | P19: =F19*I19*J19*M19 -> 6.021036 | Q19: Excludes accelerator and memory pass-through | R19: Research assumption
A20: Power, cooling and electrical | B20: 0.1 | C20: 0.13 | D20: =$F$11*B20 -> 34.0145 | E20: =$G$11*C20 -> 86.034 | F20: =E20-D20 -> 52.0195 | G20: 0.25 | H20: 0.4 | I20: 0.55 | J20: 0.75 | K20: 0.15 | L20: 0.2 | M20: 0.25 | N20: =F20*G20*J20*K20 -> 1.4630484 | O20: =F20*H20*J20*L20 -> 3.12117 | P20: =F20*I20*J20*M20 -> 5.3645109 | Q20: Higher rack density and cooling requirements | R20: Research assumption
A21: Buildings and construction | B21: 0.24 | C21: 0.15 | D21: =$F$11*B21 -> 81.6348 | E21: =$G$11*C21 -> 99.27 | F21: =E21-D21 -> 17.6352 | G21: 0.2 | H21: 0.3 | I21: 0.45 | J21: 0.65 | K21: 0.03 | L21: 0.05 | M21: 0.07 | N21: =F21*G21*J21*K21 -> 0.06877728 | O21: =F21*H21*J21*L21 -> 0.1719432 | P21: =F21*I21*J21*M21 -> 0.36108072 | Q21: Facility build-out and timing | R21: Research assumption
A22: Other, foreign and private | B22: 0.05 | C22: 0.05 | D22: =$F$11*B22 -> 17.00725 | E22: =$G$11*C22 -> 33.09 | F22: =E22-D22 -> 16.08275 | G22: 0 | H22: 0 | I22: 0 | J22: 0.5 | K22: 0 | L22: 0 | M22: 0 | N22: =F22*G22*J22*K22 -> 0 | O22: =F22*H22*J22*L22 -> 0 | P22: =F22*I22*J22*M22 -> 0 | Q22: No S&P earnings attribution | R22: Residual
A23: Total | B23: =SUM(B16:B22) -> 1 | C23: =SUM(C16:C22) -> 1 | D23: =SUM(D16:D22) -> 340.145 | E23: =SUM(E16:E22) -> 661.8 | F23: =SUM(F16:F22) -> 321.655 | N23: =SUM(N16:N22) -> 90.297927 | O23: =SUM(O16:O22) -> 120.17292 | P23: =SUM(P16:P22) -> 152.61894
A26: Important | B26: The 2025 and 2026 category shares are separate assumptions. Microsoft disclosed that higher component prices added about $25bn to its earlier 2026 capex estimate, so capex growth should not be read as physical volume growth.
A27: No vendor market share | B27: This cross-check uses aggregate S&P capture ranges by category. It deliberately removes the unsupported company-specific capture values in the prior workbook.
A28: Use | B28: Compare this range with the consensus-based company result. Do not average the two estimates or add them together.

Sheet Assumptions
I2: Company-level AI attribution assumptions
A3: Model Assumptions
A4: S&P 500 calendar-year denominator | I4: Ticker | J4: Low | K4: Base | L4: High
A5: Metric | B5: Value | C5: Unit | D5: Status / source | F5: Other input | G5: Value | H5: Unit | I5: MSFT
A6: As-of date | B6: 46288 | C6: date | D6: Update to match consensus extract | F6: Goldman broad AI-beneficiary benchmark | G6: 0.5 | H6: % of S&P earnings increase | I6: AMZN
A7: S&P 500 CY2025 adjusted EPS | B7: 274.19 | C7: index points | D7: Consensus input | F7: Required company count | G7: 40 | H7: companies | I7: GOOGL
A8: S&P 500 CY2026 adjusted EPS | B8: 360 | C8: index points | D8: Consensus input | I8: META
A9: S&P 500 CY2027 adjusted EPS | B9: 420 | C9: index points | D9: User assumption | I9: ORCL
A10: S&P 500 divisor | B10: 8.53669 | C10: USD bn per index point | D10: Dec-2025 published value; update if available | I10: NVDA
A11: 2025→2026 EPS increase | B11: =B8-B7 -> 85.81 | C11: index points | D11: Calculated | I11: AMD
A12: 2026→2027 EPS increase | B12: =B9-B8 -> 60 | C12: index points | D12: Calculated | I12: AVGO
A13: 2025→2026 aggregate earnings increase | B13: =B11*B10 -> 732.53337 | C13: USD bn | D13: Calculated | I13: MU
A14: 2026→2027 aggregate earnings increase | B14: =B12*B10 -> 512.2014 | C14: USD bn | D14: Calculated | I14: INTC
A15: AI Earnings portion by selected group | B15: 0.9 | I15: AMAT
I16: LRCX
I17: KLAC
I18: CDNS
I19: SNPS
I20: ANET
A21: Platform contribution | B21: Shows hyperscaler and platform AI profit separately from supplier earnings. The base case is intentionally narrow because non-AI cloud, advertising and retail earnings remain material. | I21: CSCO
A22: Downside sensitivity | B22: A 10% Capex cut does not cap supplier profit damage at 10%. Inventory, order cancellations, lower utilization and price declines can produce a larger profit shock. | I22: MRVL
A23: Calendar basis | B23: Use CY2025, CY2026 and CY2027. Do not mix fiscal-year values for non-December companies. | I23: GLW
A24: Earnings basis | B24: Use one comparable adjusted basis across the company sample and S&P denominator. | I24: APH
I25: LITE
I26: COHR
I27: DELL
I28: HPE
I29: SMCI
I30: WDC
I31: STX
I32: VRT
I33: ETN
I34: GEV
I35: CARR
I36: HUBB
... I44: VST

Sheet Methodology
A1: Methodology | B1: Methodology | C1: Methodology | D1: Methodology | E1: Methodology | F1: Methodology | G1: Methodology | H1: Methodology
A2: Definitions, period treatment and interpretation boundaries. | B2: Definitions, period treatment and interpretation boundaries. | C2: Definitions, period treatment and interpretation boundaries. | D2: Definitions, period treatment and interpretation boundaries. | E2: Definitions, period treatment and interpretation boundaries. | F2: Definitions, period treatment and interpretation boundaries. | G2: Definitions, period treatment and interpretation boundaries. | H2: Definitions, period treatment and interpretation boundaries.
A4: Topic | B4: Rule | C4: Formula / example | D4: Why it matters | E4: Input owner | F4: Output | G4: Risk | H4: Treatment
A5: Primary numerator | B5: Selected companies' CY2026 minus CY2025 and CY2027 minus CY2026 adjusted net income | C5: Σ(NI26-NI25); Σ(NI27-NI26) | D5: Closest public comparison with a beneficiary basket | E5: User consensus extract | F5: Broad basket contribution | G5: Basket selection | H5: Show separately
A6: AI attribution | B6: Apply low/base/high company-specific AI shares | C6: ΔNI × attribution | D6: Separates beneficiary status from causal attribution | E6: Research assumption | F6: AI-attributed range | G6: Judgment | H6: Editable
A7: Denominator | B7: S&P CY EPS change multiplied by divisor | C7: (EPS26-EPS25) × divisor; (EPS27-EPS26) × divisor | D7: Converts index points to aggregate dollars | E7: Same provider/date preferred | F7: S&P earnings increase | G7: Divisor changes | H7: Update input
A8: Calendarization | B8: Use calendar-year estimates for every company in CY2025–CY2027 | C8: Quarter sum preferred | D8: Prevents mixed FY periods | E8: Data provider or user | F8: Comparable earnings | G8: Seasonality | H8: Do not mix FY and CY
A9: Alternative input | B9: Calendarized EPS × diluted shares | C9: EPS × shares bn = USD bn | D9: Used only when net income unavailable | E9: User consensus extract | F9: Company earnings | G9: Share forecast error | H9: Fallback only
A10: Capex cross-check | B10: Category-level capex change × S&P capture × recognition × margin | C10: ΔCapex × capture × recognition × margin | D10: Checks order of magnitude | E10: Research assumptions | F10: Direct-profit range | G10: Price versus volume | H10: Secondary
A11: No addition rule | B11: Do not add consensus and capex results | C11: Separate estimates | D11: They measure overlapping earnings | E11: Model rule | F11: Two views | G11: Double counting | H11: Compare only
A12: Missing data | B12: Leave headline output blank until complete | C12: No zero substitution | D12: Prevents understated contribution | E12: Workbook control | F12: Awaiting inputs | G12: False precision | H12: Gated output
A13: Platform AI contribution | B13: Hyperscaler and platform earnings increase × attribution range | C13: Separate from suppliers | D13: Avoids treating all platform profit growth as AI | E13: Research assumption | F13: Platform range | G13: Disclosure limits | H13: Show low/base/high
A14: Supplier downside sensitivity | B14: Supplier AI-attributed incremental profit × shock rate ÷ divisor ÷ total S&P 500 EPS | C14: 10%, 20%, 30% supplier-profit shock cases | D14: Shows inventory, price and utilization non-linearity | E14: Research scenario | F14: EPS change and % | G14: Not a forecast | H14: Keep separate from base case
A15: Company type | B15: CY conversion if annual data only | C15: Example | D15: Preferred replacement | E15: Current model rule | F15: Confidence | G15: Note
A16: December year-end | B16: FY2026 = CY2026 | C16: Amazon, Alphabet, Meta | D16: Use FY directly | E16: No conversion | F16: High | G16: Confirm exact period end
A17: June year-end | B17: 6/12 FY26 + 6/12 FY27 | C17: Microsoft | D17: Calendar-quarter sum | E17: User supplies CY | F17: Medium | G17: Annual weighting is approximate
A18: May year-end | B18: 5/12 FY26 + 7/12 FY27 | C18: Oracle | D18: Calendar-quarter sum | E18: User supplies CY | F18: Medium | G18: AI capex is highly uneven
A19: January year-end | B19: 1/12 FY26 + 11/12 FY27 | C19: NVIDIA, Dell, Marvell | D19: Calendar-quarter sum | E19: User supplies CY | F19: Low | G19: Fast growth makes weighting imprecise
A20: October year-end | B20: 10/12 FY26 + 2/12 FY27 | C20: Broadcom, HPE, AMAT, Synopsys | D20: Calendar-quarter sum | E20: User supplies CY | F20: Medium | G20: Acquisitions can distort comparability
A21: Other | B21: Weight by months only as fallback | C21: Micron, Cisco, JCI | D21: Calendarized provider field | E21: User supplies CY | F21: Medium | G21: Document the method

Sheet Sources
A1: Sources | B1: Sources | C1: Sources | D1: Sources | E1: Sources | F1: Sources
A2: Public references support the framework. Yellow research assumptions remain distinct from source data. | B2: Public references support the framework. Yellow research assumptions remain distinct from source data. | C2: Public references support the framework. Yellow research assumptions remain distinct from source data. | D2: Public references support the framework. Yellow research assumptions remain distinct from source data. | E2: Public references support the framework. Yellow research assumptions remain distinct from source data. | F2: Public references support the framework. Yellow research assumptions remain distinct from source data.
A4: ID | B4: Date | C4: Publisher | D4: Used for | E4: URL | F4: Status
A5: S01 | B5: 46170 | C5: Goldman Sachs Research | D5: CY2026 S&P EPS $340; hyperscaler capex $754bn; beneficiaries about half of earnings growth | E5: https://www.goldmansachs.com/insights/articles/s-and-p-500-forecast-to-climb-as-earnings-growth-powers-stocks-higher | F5: External forecast
A6: S02 | B6: 46023 | C6: FactSet | D6: S&P bottom-up EPS aggregates median CY estimates for index companies | E6: https://insight.factset.com/are-industry-analysts-overestimating-sp-500-eps-for-2026 | F6: Method reference
A7: S03 | B7: 46022 | C7: YCharts / S&P data | D7: S&P 500 divisor 8,536.69 million | E7: https://ycharts.com/indicators/sp_500_divisor | F7: Historical value
A8: S04 | B8: 46141 | C8: Microsoft | D8: About $25bn of earlier CY2026 capex estimate related to higher component pricing | E8: https://www.microsoft.com/en-us/investor/events/fy-2026/earnings-fy-2026-q3 | F8: Company disclosure
A9: S05 | B9: 45959 | C9: Alphabet | D9: About 60% of technical infrastructure capex in servers and 40% in data centers and networking | E9: https://abc.xyz/investor/events/event-details/2025/2025-Q3-Earnings-Call-2025-4OI4Bac_Q9/default.aspx | F9: Company disclosure
A10: S06 | B10: 46156 | C10: Epoch AI | D10: Stylized 1GW AI data-center cost breakdown | E10: https://epoch.ai/data-insights/ai-datacenter-cost-breakdown | F10: External model
A11: S07 | B11: 46225 | C11: Reuters / LSEG | D11: Companies do not consistently disclose AI-only capex | E11: https://www.reuters.com/business/ai-investment-boom-puts-big-techs-free-cash-flow-under-pressure-2026-07-22/ | F11: External estimate
A12: S08 | B12: 46288 | C12: S&P Dow Jones Indices | D12: Current constituent framework and 2026 additions including VRT, LITE, COHR and MRVL | E12: https://www.spglobal.com/spdji/en/indices/equity/sp-500/ | F12: Index membership
A13: S09 | B13: 46288 | C13: Model research | D13: Company AI-attribution ranges and category capture/margin ranges | E13: Internal workbook assumptions | F13: Research assumption
